Input_Data/pop_data.csv
Artist,Genre,key,mode,valence,tempo,year,speechiness,instrumentalness,time_signature
Madness,Pop,G#,Minor,0.5579999999999999,81.03,2014.0,0.3,0.0,4.0
Alexandra Savior,Pop,F#,Minor,0.7979999999999999,107.051,2017.0,0.0352,0.00395,4.0
Prefab Sprout,Pop,C,Major,0.17600000000000002,119.997,1989.0,0.0449,0.0008349999999999999,4.0
Roxette,Pop,G,Major,0.457,172.583,1991.0,0.0462,0.000168,4.0
*NSYNC,Pop,A#,Major,0.294,168.00099999999995,2005.0,0.0436,0.0,4.0
Belle & Sebastian,Pop,D,Major,0.621,99.421,2013.0,0.0284,0.0177,4.0
Britney Spears,Pop,B,Major,0.659,110.001,2000.0,0.0376,3.17e-05,4.0
Dionne Warwick,Pop,B,Minor,0.6,123.994,1967.0,0.0525,0.0,4.0
Bow Wow Wow,Pop,G#,Major,0.967,132.59799999999998,1996.0,0.0585,0.000145,4.0
Duran Duran,Pop,C#,Major,0.597,113.448,2018.0,0.0473,0.0,4.0
Dionne Warwick,Pop,D#,Minor,0.7929999999999999,108.697,1973.0,0.0491,0.00116,4.0
Britney Spears,Pop,C,Minor,0.968,107.988,2004.0,0.0366,2.96e-06,4.0
Danni Carlos,Pop,G,Minor,0.303,124.116,2003.0,0.0296,0.000167,4.0
Cher,Pop,A,Major,0.381,172.435,1969.0,0.0364,0.0,4.0
Cher,Pop,A,Major,0.447,172.799,1969.0,0.0338,0.0,4.0
Duran Duran,Pop,A,Minor,0.464,126.979,2007.0,0.0745,0.000114,4.0
Cher,Pop,D,Major,0.365,92.751,2019.0,0.0287,0.0,4.0
Cher,Pop,D,Major,0.365,92.751,1969.0,0.0287,0.0,4.0
Dionne Warwick,Pop,F,Major,0.0868,74.919,1968.0,0.0352,2.21e-06,4.0
Dionne Warwick,Pop,F,Major,0.0734,76.317,2016.0,0.032,1.88e-06,4.0
Dionne Warwick,Pop,C,Major,0.8540000000000001,92.616,2005.0,0.104,1.97e-05,4.0
Dionne Warwick,Pop,C#,Major,0.785,158.036,2012.0,0.0697,1.7800000000000002e-05,4.0
Dionne Warwick,Pop,A#,Major,0.27,135.95,1992.0,0.0298,7.13e-06,4.0
Britney Spears,Pop,C,Minor,0.96,104.001,1999.0,0.0341,0.0,4.0
Britney Spears,Pop,G#,Major,0.7490000000000001,101.068,2004.0,0.0426,0.000108,4.0
Kelly Clarkson,Pop,B,Major,0.22,119.61,2002.0,0.0337,0.0,3.0
Carole King,Pop,A,Major,0.303,85.492,1971.0,0.0289,0.00135,3.0
Carole King,Pop,A,Major,0.28300000000000003,129.99,2017.0,0.0394,0.0,4.0
Kudai,Pop,F#,Major,0.14300000000000002,74.992,2017.0,0.0333,0.281,4.0
Britney Spears,Pop,C,Minor,0.883,92.96,2004.0,0.0315,5.56e-05,4.0
Prefab Sprout,Pop,C,Minor,0.395,121.111,2003.0,0.0347,0.28,4.0
Blake Lewis,Pop,E,Minor,0.332,126.636,2007.0,0.0438,3.74e-05,4.0
Taylor Swift,Pop,D,Major,0.407,160.093,2018.0,0.173,0.0,4.0
Miley Cyrus,Pop,B,Minor,0.398,102.974,2015.0,0.0411,7.04e-06,4.0
Beyoncé,Pop,F#,Major,0.261,63.345,2011.0,0.0339,5.14e-06,5.0
Cimorelli,Pop,F,Minor,0.258,93.167,2017.0,0.0312,0.0,4.0
Dionne Warwick,Pop,D,Major,0.746,100.879,2005.0,0.0514,0.00013700000000000002,4.0
Blake Lewis,Pop,D,Major,0.555,120.023,2007.0,0.036000000000000004,3.27e-05,4.0
Michael Jackson,Pop,C#,Major,0.52,103.962,1995.0,0.249,9.34e-06,4.0
Michael Jackson,Pop,C,Major,0.242,90.503,2001.0,0.155,0.0116,4.0
Blue,Pop,C,Minor,0.465,119.931,2011.0,0.061,0.00133,4.0
Becky G,Pop,F,Minor,0.892,91.99,2019.0,0.0896,1.16e-05,4.0
Big Time Rush,Pop,F,Minor,0.851,90.006,2013.0,0.0713,0.0,4.0
Bruno Mars,Pop,C#,Major,0.632,106.97,2016.0,0.0797,0.0,4.0
The Cardigans,Pop,C,Major,0.402,129.952,2004.0,0.0299,0.0,4.0
Meghan Trainor,Pop,D,Major,0.675,170.06099999999995,2015.0,0.0967,0.000401,4.0
James Blunt,Pop,C,Major,0.501,102.072,2020.0,0.0447,0.0,4.0
James Blunt,Pop,C,Major,0.4370000000000001,104.99,2020.0,0.0338,0.0,4.0
Beyoncé,Pop,A,Minor,0.56,136.024,2014.0,0.126,0.0,4.0
Beyoncé,Pop,A,Minor,0.383,136.084,2019.0,0.18,0.0,4.0
Roxette,Pop,C,Major,0.5529999999999999,137.105,2011.0,0.0464,0.000201,4.0
Mariah Carey,Pop,A#,Major,0.184,126.938,2018.0,0.0599,0.0,4.0
David Archuleta,Pop,F#,Minor,0.6829999999999999,97.938,2020.0,0.204,2.18e-05,4.0
Cyndi Lauper,Pop,C,Major,0.835,144.102,1986.0,0.0441,0.000242,4.0
Dionne Warwick,Pop,C,Minor,0.246,108.04,2012.0,0.0278,0.006220000000000001,4.0
Eliana,Pop,C,Major,0.963,149.35299999999995,1995.0,0.101,0.0,4.0
Sandy,Pop,C,Major,0.72,190.022,2000.0,0.0894,0.0,4.0
Eliana,Pop,B,Major,0.969,150.398,1995.0,0.0551,7.170000000000001e-05,4.0
Eliana,Pop,A,Major,0.574,116.944,2001.0,0.0472,0.0,3.0
Joni Mitchell,Pop,G#,Major,0.14800000000000002,86.53299999999999,2000.0,0.0332,0.132,4.0
Joni Mitchell,Pop,D#,Major,0.556,99.824,1974.0,0.14800000000000002,0.0,4.0
Anggun,Pop,C#,Major,0.534,86.913,2008.0,0.109,5.76e-05,4.0
Reik,Pop,C,Major,0.348,131.991,2012.0,0.0296,0.0,4.0
Eliana,Pop,G#,Minor,0.953,103.167,2000.0,0.0784,1.3e-05,4.0
Little Mix,Pop,A#,Minor,0.6,114.468,2013.0,0.07400000000000001,0.0,4.0
George Michael,Pop,F#,Major,0.165,99.178,2006.0,0.0291,0.0212,4.0
Eliana,Pop,A,Major,0.486,174.109,1993.0,0.141,0.0,4.0
Rick Astley,Pop,D,Minor,0.468,88.44,1993.0,0.0384,2.7000000000000004e-06,4.0
Eliana,Pop,C#,Minor,0.929,145.908,2000.0,0.0417,0.0,4.0
Eliana,Pop,A,Major,0.971,129.939,2000.0,0.0345,0.0,4.0
Eliana,Pop,C,Major,0.973,142.83100000000005,2001.0,0.0338,5.21e-05,4.0
Nancy Sinatra,Pop,A,Major,0.29100000000000004,117.899,2009.0,0.0342,0.0,4.0
The Cardigans,Pop,G#,Major,0.519,96.659,2004.0,0.0331,0.0002,4.0
Mike,Pop,A,Major,0.711,88.001,2006.0,0.0373,0.93,4.0
Dionne Warwick,Pop,D,Major,0.6990000000000001,112.666,1969.0,0.0471,0.0,4.0
Dionne Warwick,Pop,F,Major,0.246,72.58800000000002,1989.0,0.033,3.04e-05,4.0
Dionne Warwick,Pop,F,Major,0.272,71.868,2019.0,0.0347,0.00154,4.0
Dionne Warwick,Pop,F,Major,0.272,71.868,1964.0,0.0347,0.00154,4.0
Dionne Warwick,Pop,F,Major,0.333,101.54,2018.0,0.0307,2.23e-05,3.0
Dionne Warwick,Pop,F,Major,0.378,73.10600000000002,2018.0,0.0334,0.000195,4.0
George Michael,Pop,B,Minor,0.613,99.161,1987.0,0.0414,0.74,4.0
Jessica Simpson,Pop,E,Minor,0.79,188.001,2001.0,0.136,0.0,4.0
Leighton Meester,Pop,D,Major,0.219,147.954,2010.0,0.0513,0.0,4.0
Erasure,Pop,C,Major,0.7240000000000001,113.815,2017.0,0.0291,1.72e-06,4.0
Erasure,Pop,C,Major,0.6679999999999999,114.099,2018.0,0.0269,1.33e-05,4.0
David Archuleta,Pop,C,Minor,0.5379999999999999,163.97799999999995,2008.0,0.0321,0.0,3.0
Adam Lambert,Pop,F,Major,0.511,145.002,2009.0,0.0467,0.108,4.0
Josh Rouse,Pop,G,Major,0.7070000000000001,136.57399999999998,2013.0,0.0341,0.000243,4.0
Dionne Warwick,Pop,C,Major,0.343,133.218,1982.0,0.0269,2.45e-06,4.0
Little Mix,Pop,A#,Major,0.542,104.053,2020.0,0.0709,0.0,4.0
Olly Murs,Pop,D,Major,0.381,180.192,2010.0,0.0369,0.0,4.0
Kelly Clarkson,Pop,G,Minor,0.5579999999999999,103.133,2017.0,0.079,0.000819,4.0
Kelly Clarkson,Pop,G#,Major,0.134,144.814,2002.0,0.0315,3.71e-05,4.0
Leona Lewis,Pop,G#,Major,0.152,69.124,2007.0,0.029,7.46e-06,4.0
Carole King,Pop,C,Minor,0.249,114.34,1974.0,0.0302,5.06e-05,4.0
Cyndi Lauper,Pop,G,Major,0.541,119.883,1989.0,0.0359,0.0007059999999999999,4.0
Mariah Carey,Pop,D,Major,0.705,89.994,2018.0,0.16399999999999998,0.0,4.0
Eliana,Pop,A,Major,0.969,132.391,1995.0,0.04,0.0,5.0
Cyndi Lauper,Pop,C,Major,0.725,104.006,1993.0,0.109,0.000338,4.0
Ana Carolina,Pop,A,Minor,0.505,83.946,2017.0,0.7879999999999999,5.47e-06,4.0
Michael Jackson,Pop,B,Minor,0.424,118.752,2014.0,0.305,3.45e-06,4.0
Michael Jackson,Pop,E,Minor,0.888,118.752,2014.0,0.061,0.0,4.0
Prefab Sprout,Pop,G,Major,0.34,121.432,1997.0,0.0275,0.00026000000000000003,4.0
Anggun,Pop,C#,Major,0.375,158.99,1998.0,0.0332,2.33e-05,4.0
Eliana,Pop,B,Major,0.989,132.41299999999998,1999.0,0.0348,0.0,4.0
David Archuleta,Pop,A#,Major,0.508,91.991,2009.0,0.0329,0.0,4.0
Vanessa Carlton,Pop,B,Major,0.342,87.132,2017.0,0.0333,0.0,4.0
Christina Perri,Pop,A#,Major,0.161,139.028,2011.0,0.0267,0.000961,3.0
Julieta Venegas,Pop,F,Minor,0.964,127.97,2003.0,0.0353,0.0165,4.0
Jaci Velasquez,Pop,B,Major,0.34700000000000003,149.88,2003.0,0.0284,0.0,4.0
Jaci Velasquez,Pop,G#,Major,0.191,81.57600000000002,2003.0,0.0252,0.0,4.0
Little Mix,Pop,A,Minor,0.6659999999999999,129.915,2015.0,0.0435,0.0,4.0
One Direction,Pop,D#,Major,0.506,141.839,2015.0,0.0309,0.0,4.0
Eliana,Pop,A,Major,0.289,128.433,1995.0,0.0285,0.0,4.0
Meghan Trainor,Pop,E,Major,0.173,86.01899999999998,2019.0,0.0248,0.0,4.0
Meghan Trainor,Pop,B,Minor,0.366,112.072,2019.0,0.032,0.0,4.0
Shania Twain,Pop,D#,Major,0.815,156.38,1996.0,0.0469,0.0,4.0
Kudai,Pop,F#,Major,0.308,145.994,2017.0,0.0878,2.59e-06,4.0
