Output_Data/pop_word_count.csv
words,0
.,362000
",",160869
you,138360
i,128865
the,112297
to,74641
and,68646
me,66979
a,59119
it,52670
my,47480
in,38857
your,34718
i'm,33891
that,33240
on,30889
love,28349
of,28045
oh,27374
be,27064
all,27035
don't,25121
we,24647
is,24435
know,24199
for,23768
so,23524
like,21917
but,20782
just,20183
it's,19487
up,19198
no,18196
?,18183
do,17728
this,17705
with,17204
what,17182
can,17081
when,16908
you're,15951
get,15888
now,15815
got,15531
if,14890
baby,14872
go,14712
down,12348
yeah,12209
one,12198
time,11957
want,11896
out,11861
see,11578
not,11509
are,11501
never,11327
let,11229
can't,10687
make,10289
say,10102
come,9870
have,9684
wanna,9480
gonna,9344
!,9305
was,9282
way,9280
take,9219
will,8962
i'll,8564
girl,8246
feel,8185
they,8180
back,8154
she,8123
how,7995
need,7834
right,7689
at,7665
heart,7435
from,7402
here,7214
there,7156
life,6929
i've,6847
tell,6809
night,6794
give,6720
could,6690
away,6640
been,6629
'cause,6288
more,6154
he,6061
as,5907
about,5866
think,5742
her,5741
la,5739
only,5707
world,5635
why,5491
keep,5467
where,5458
there's,5444
day,5417
too,5203
won't,5183
ain't,5126
by,5080
good,5060
that's,5037
over,4955
cause,4875
we're,4853
around,4781
little,4739
then,4731
every,4691
through,4545
look,4515
again,4506
who,4431
or,4419
hey,4401
would,4304
some,4289
tonight,4263
our,4258
always,4212
still,4199
am,4176
us,4170
ooh,4124
gotta,4111
ever,4100
better,4092
eyes,4031
boy,4030
had,4012
said,4008
nothing,3931
mind,3885
chorus,3877
na,3872
man,3860
find,3761
long,3701
things,3695
really,3686
stop,3660
put,3587
were,3544
hold,3524
them,3475
something,3433
show,3348
everything,3321
hear,3318
gone,3219
home,3213
turn,3202
ya,3200
try,3168
much,3149
well,3113
you'll,3063
thing,3057
believe,3030
let's,3023
even,2977
leave,2938
off,2929
before,2911
going,2874
dance,2862
an,2856
you've,2848
stay,2847
into,2836
his,2801
alone,2783
without,2779
than,2768
live,2751
fall,2727
light,2720
him,2696
call,2690
did,2687
run,2685
she's,2634
hard,2610
should,2601
feeling,2573
bad,2567
inside,2530
made,2501
these,2498
face,2486
new,2484
i'd,2421
please,2412
play,2391
another,2371
cry,2352
head,2335
work,2325
place,2316
care,2302
last,2274
left,2267
break,2264
da,2208
wrong,2204
waiting,2202
hands,2199
crazy,2198
free,2193
uh,2183
enough,2179
girls,2176
t,2174
mine,2172
body,2159
move,2149
change,2142
people,2137
looking,2134
same,2103
he's,2090
coming,2088
money,2084
maybe,2080
end,2068
together,2053
myself,2043
s,2037
thought,2018
ah,2017
lost,2016
touch,2002
name,1991
true,1979
wish,1976
own,1972
forever,1950
walk,1940
has,1937
sun,1931
everybody,1911
bring,1898
side,1894
high,1892
dream,1883
wait,1870
talk,1848
best,1831
hand,1826
song,1793
sky,1788
real,1785
we'll,1777
someone,1760
lose,1753
sweet,1752
trying,1729
what's,1714
fire,1706
two,1702
kiss,1691
rain,1686
party,1686
yes,1667
didn't,1662
hope,1659
getting,1650
close,1645
other,1640
beat,1638
fight,1623
alright,1620
makes,1617
start,1616
used,1615
far,1597
m,1582
round,1582
done,1571
o,1569
while,1568
its,1567
fly,1552
nobody,1550
comes,1548
found,1545
knew,1544
ready,1541
stand,1539
feels,1536
words,1536
remember,1530
pain,1526
sing,1521
shake,1510
watch,1507
help,1500
must,1494
forget,1492
rock,1483
christmas,1482
told,1470
because,1465
somebody,1464
until,1461
happy,1458
lonely,1456
beautiful,1451
old,1440
might,1430
hurt,1430
big,1428
goodbye,1420
door,1414
their,1412
goes,1403
matter,1395
lights,1393
dreams,1393
eh,1381
smile,1378
days,1375
die,1373
those,1372
times,1371
else,1370
knows,1350
living,1345
till,1342
anything,1339
floor,1333
mean,1332
soul,1330
came,1315
'em,1312
blue,1303
cold,1301
friends,1298
sometimes,1297
after,1294
ride,1294
first,1294
friend,1282
today,1276
falling,1275
lie,1271
many,1269
though,1260
under,1251
hot,1249
once,1248
music,1247
understand,1241
whoa,1238
running,1237
tears,1226
yourself,1220
sleep,1218
miss,1216
hit,1214
took,1211
easy,1203
sure,1202
morning,1197
stars,1197
deep,1187
boys,1172
late,1166
listen,1165
line,1165
town,1164
dark,1159
chance,1156
shit,1149
game,1149
open,1148
air,1139
thinking,1124
fine,1117
guess,1116
seen,1112
young,1112
truth,1107
hate,1106
strong,1105
shine,1102
god,1100
couldn't,1099
broken,1097
may,1096
we've,1092
they're,1090
doing,1086
arms,1084
any,1078
sound,1076
making,1073
control,1073
city,1073
wanted,1071
doesn't,1056
alive,1056
behind,1053
next,1053
sorry,1047
whole,1040
set,1018
hide,1018
kind,999
save,995
heard,993
babe,989
bitch,978
wake,978
anymore,974
star,963
ask,960
fuck,957
pretty,956
breathe,956
each,953
roll,950
ground,946
you'd,946
slow,940
saw,940
apart,937
tried,936
standing,935
feet,934
wild,933
low,932
does,930
being,923
step,922
lies,918
loving,912
seems,912
top,911
room,911
dirty,909
fun,907
talking,906
dancing,902
taking,900
2,899
who's,897
such,892
fool,892
u,891
learn,884
gave,883
moment,882
re,872
wonder,869
since,867
wants,864
damn,863
road,858
reason,856
bed,855
burn,852
part,851
ha,847
throw,846
saying,841
whatever,840
black,840
heaven,831
yo,828
walking,823
honey,823
very,821
perfect,817
gets,813
breath,811
boom,805
felt,803
cool,802
takes,801
hearts,800
wind,799
lot,798
ohh,797
afraid,797
loved,794
bang,793
don,792
word,792
blow,789
along,786
worth,784
mama,784
calling,784
red,780
fast,776
follow,775
went,773
wouldn't,769
white,760
jump,760
meet,759
everyone,759
catch,754
between,745
woah,744
years,739
bright,735
both,733
moving,732
woman,728
already,726
moon,722
bit,718
seem,717
house,714
holding,713
drop,712
lay,711
past,711
soon,710
promise,710
burning,708
angel,708
street,707
yours,705
tomorrow,704
eye,703
'bout,702
full,700
lover,697
giving,697
drink,696
hell,695
sexy,693
three,690
summer,690
ba,688
car,687
started,682
somewhere,681
phone,681
tight,680
trust,674
voice,673
gon',672
use,668
meant,666
club,666
skin,665
verse,665
tired,661
ay,658
above,656
fear,655
nights,654
lips,651
pull,649
caught,648
different,648
playing,645
sad,640
water,640
rest,637
b,636
losing,635
born,634
reach,634
'til,634
hair,628
lady,626
finally,623
huh,617
cuz,614
loud,612
watching,612
says,609
anyone,608
singing,608
breaking,608
repeat,607
clear,603
ass,603
minute,602
keeps,599
doo,597
pick,597
blame,597
met,596
higher,596
okay,595
closer,590
sea,578
everyday,578
nah,577
thank,575
scared,573
swear,573
picture,572
less,568
carry,566
d,566
pop,566
spend,565
daddy,564
1,564
gimme,560
;,559
crying,557
number,557
telling,557
leaving,556
hurts,555
turned,551
story,550
faith,550
year,550
dead,549
bye,549
earth,546
guy,546
gold,546
pay,545
drive,545
wasn't,544
cut,542
near,542
darling,541
child,540
im,540
outside,540
dreaming,538
everywhere,537
wall,531
happen,531
isn't,530
shot,530
loves,529
blind,528
ll,527
win,525
dont,522
speak,521
e,521
l,521
space,520
push,518
bridge,516
known,516
nowhere,516
needs,513
four,513
sit,512
mad,512
straight,512
pretend,512
kill,511
nigga,510
love's,505
secret,505
river,504
upon,504
hello,504
taste,503
lovin',503
send,502
worry,502
missing,502
second,501
akon,497
stuck,495
dear,494
lord,494
joy,492
nice,491
king,491
most,489
turning,489
million,489
act,489
window,488
across,487
belong,486
knees,486
yea,486
half,484
front,481
read,480
power,478
kids,476
peace,474
cos,473
bout,472
snow,472
em,471
empty,471
feelings,471
share,468
someday,468
feelin',467
war,467
blood,464
g,463
scream,462
lead,461
cannot,461
everybody's,461
looks,460
trouble,458
lives,458
sick,457
radio,457
ring,455
mother,454
treat,454
ok,452
n,451
called,451
x2,448
special,448
middle,448
shout,447
broke,443
mouth,443
somehow,441
mr,440
ahead,439
gun,438
rise,438
i'mma,437
ones,436
fighting,435
walked,434
single,434
fill,433
anyway,433
y,431
dj,430
warm,430
waste,428
miles,427
five,426
ladies,422
doubt,421
tear,420
ho,419
oooh,419
laugh,419
changed,419
ways,419
fell,419
i'ma,418
check,418
3,417
wings,415
de,414
grow,410
streets,409
yesterday,407
lying,407
bet,407
shame,405
sitting,404
pray,404
freedom,404
against,404
pass,404
working,402
means,402
mirror,401
land,399
thousand,399
glass,399
memories,398
shining,396
